Internal Server Error: /sitemap.xml
Traceback (most recent call last):
  File "D:\work\clients_2023\senv\lib\site-packages\django\contrib\sites\models.py", line 39, in _get_site_by_request
    SITE_CACHE[host] = self.get(domain__iexact=host)
  File "D:\work\clients_2023\senv\lib\site-packages\django\db\models\manager.py", line 85, in manager_method
    return getattr(self.get_queryset(), name)(*args, **kwargs)
  File "D:\work\clients_2023\senv\lib\site-packages\django\db\models\query.py", line 650, in get
    raise self.model.DoesNotExist(
django.contrib.sites.models.Site.DoesNotExist: Site matching query does not exist.

During handling of the above exception, another exception occurred:

Traceback (most recent call last):
  File "D:\work\clients_2023\senv\lib\site-packages\django\core\handlers\exception.py", line 56, in inner
    response = get_response(request)
  File "D:\work\clients_2023\senv\lib\site-packages\django\core\handlers\base.py", line 197, in _get_response
    response = wrapped_callback(request, *callback_args, **callback_kwargs)
  File "D:\work\clients_2023\senv\lib\site-packages\django\contrib\sitemaps\views.py", line 34, in inner
    response = func(request, *args, **kwargs)
  File "D:\work\clients_2023\senv\lib\site-packages\django\contrib\sitemaps\views.py", line 111, in sitemap
    req_site = get_current_site(request)
  File "D:\work\clients_2023\senv\lib\site-packages\django\contrib\sites\shortcuts.py", line 16, in get_current_site
    return Site.objects.get_current(request)
  File "D:\work\clients_2023\senv\lib\site-packages\django\contrib\sites\models.py", line 61, in get_current
    return self._get_site_by_request(request)
  File "D:\work\clients_2023\senv\lib\site-packages\django\contrib\sites\models.py", line 45, in _get_site_by_request
    SITE_CACHE[domain] = self.get(domain__iexact=domain)
  File "D:\work\clients_2023\senv\lib\site-packages\django\db\models\manager.py", line 85, in manager_method
    return getattr(self.get_queryset(), name)(*args, **kwargs)
  File "D:\work\clients_2023\senv\lib\site-packages\django\db\models\query.py", line 650, in get
    raise self.model.DoesNotExist(
django.contrib.sites.models.Site.DoesNotExist: Site matching query does not exist.
"GET /sitemap.xml HTTP/1.1" 500 108899
Internal Server Error: /sitemap.xml
Traceback (most recent call last):
  File "D:\work\clients_2023\senv\lib\site-packages\django\contrib\sites\models.py", line 39, in _get_site_by_request
    SITE_CACHE[host] = self.get(domain__iexact=host)
  File "D:\work\clients_2023\senv\lib\site-packages\django\db\models\manager.py", line 85, in manager_method
    return getattr(self.get_queryset(), name)(*args, **kwargs)
  File "D:\work\clients_2023\senv\lib\site-packages\django\db\models\query.py", line 650, in get
    raise self.model.DoesNotExist(
django.contrib.sites.models.Site.DoesNotExist: Site matching query does not exist.

During handling of the above exception, another exception occurred:

Traceback (most recent call last):
  File "D:\work\clients_2023\senv\lib\site-packages\django\core\handlers\exception.py", line 56, in inner
    response = get_response(request)
  File "D:\work\clients_2023\senv\lib\site-packages\django\core\handlers\base.py", line 197, in _get_response
    response = wrapped_callback(request, *callback_args, **callback_kwargs)
  File "D:\work\clients_2023\senv\lib\site-packages\django\contrib\sitemaps\views.py", line 34, in inner
    response = func(request, *args, **kwargs)
  File "D:\work\clients_2023\senv\lib\site-packages\django\contrib\sitemaps\views.py", line 111, in sitemap
    req_site = get_current_site(request)
  File "D:\work\clients_2023\senv\lib\site-packages\django\contrib\sites\shortcuts.py", line 16, in get_current_site
    return Site.objects.get_current(request)
  File "D:\work\clients_2023\senv\lib\site-packages\django\contrib\sites\models.py", line 61, in get_current
    return self._get_site_by_request(request)
  File "D:\work\clients_2023\senv\lib\site-packages\django\contrib\sites\models.py", line 45, in _get_site_by_request
    SITE_CACHE[domain] = self.get(domain__iexact=domain)
  File "D:\work\clients_2023\senv\lib\site-packages\django\db\models\manager.py", line 85, in manager_method
    return getattr(self.get_queryset(), name)(*args, **kwargs)
  File "D:\work\clients_2023\senv\lib\site-packages\django\db\models\query.py", line 650, in get
    raise self.model.DoesNotExist(
django.contrib.sites.models.Site.DoesNotExist: Site matching query does not exist.
"GET /sitemap.xml HTTP/1.1" 500 108680
Internal Server Error: /sitemap.xml
Traceback (most recent call last):
  File "D:\work\clients_2023\senv\lib\site-packages\django\contrib\sites\models.py", line 39, in _get_site_by_request
    SITE_CACHE[host] = self.get(domain__iexact=host)
  File "D:\work\clients_2023\senv\lib\site-packages\django\db\models\manager.py", line 85, in manager_method
    return getattr(self.get_queryset(), name)(*args, **kwargs)
  File "D:\work\clients_2023\senv\lib\site-packages\django\db\models\query.py", line 650, in get
    raise self.model.DoesNotExist(
django.contrib.sites.models.Site.DoesNotExist: Site matching query does not exist.

During handling of the above exception, another exception occurred:

Traceback (most recent call last):
  File "D:\work\clients_2023\senv\lib\site-packages\django\core\handlers\exception.py", line 56, in inner
    response = get_response(request)
  File "D:\work\clients_2023\senv\lib\site-packages\django\core\handlers\base.py", line 197, in _get_response
    response = wrapped_callback(request, *callback_args, **callback_kwargs)
  File "D:\work\clients_2023\senv\lib\site-packages\django\contrib\sitemaps\views.py", line 34, in inner
    response = func(request, *args, **kwargs)
  File "D:\work\clients_2023\senv\lib\site-packages\django\contrib\sitemaps\views.py", line 111, in sitemap
    req_site = get_current_site(request)
  File "D:\work\clients_2023\senv\lib\site-packages\django\contrib\sites\shortcuts.py", line 16, in get_current_site
    return Site.objects.get_current(request)
  File "D:\work\clients_2023\senv\lib\site-packages\django\contrib\sites\models.py", line 61, in get_current
    return self._get_site_by_request(request)
  File "D:\work\clients_2023\senv\lib\site-packages\django\contrib\sites\models.py", line 45, in _get_site_by_request
    SITE_CACHE[domain] = self.get(domain__iexact=domain)
  File "D:\work\clients_2023\senv\lib\site-packages\django\db\models\manager.py", line 85, in manager_method
    return getattr(self.get_queryset(), name)(*args, **kwargs)
  File "D:\work\clients_2023\senv\lib\site-packages\django\db\models\query.py", line 650, in get
    raise self.model.DoesNotExist(
django.contrib.sites.models.Site.DoesNotExist: Site matching query does not exist.
"GET /sitemap.xml HTTP/1.1" 500 108786
Internal Server Error: /sitemap.xml
Traceback (most recent call last):
  File "D:\work\clients_2023\senv\lib\site-packages\django\contrib\sites\models.py", line 39, in _get_site_by_request
    SITE_CACHE[host] = self.get(domain__iexact=host)
  File "D:\work\clients_2023\senv\lib\site-packages\django\db\models\manager.py", line 85, in manager_method
    return getattr(self.get_queryset(), name)(*args, **kwargs)
  File "D:\work\clients_2023\senv\lib\site-packages\django\db\models\query.py", line 650, in get
    raise self.model.DoesNotExist(
django.contrib.sites.models.Site.DoesNotExist: Site matching query does not exist.

During handling of the above exception, another exception occurred:

Traceback (most recent call last):
  File "D:\work\clients_2023\senv\lib\site-packages\django\core\handlers\exception.py", line 56, in inner
    response = get_response(request)
  File "D:\work\clients_2023\senv\lib\site-packages\django\core\handlers\base.py", line 197, in _get_response
    response = wrapped_callback(request, *callback_args, **callback_kwargs)
  File "D:\work\clients_2023\senv\lib\site-packages\django\contrib\sitemaps\views.py", line 34, in inner
    response = func(request, *args, **kwargs)
  File "D:\work\clients_2023\senv\lib\site-packages\django\contrib\sitemaps\views.py", line 111, in sitemap
    req_site = get_current_site(request)
  File "D:\work\clients_2023\senv\lib\site-packages\django\contrib\sites\shortcuts.py", line 16, in get_current_site
    return Site.objects.get_current(request)
  File "D:\work\clients_2023\senv\lib\site-packages\django\contrib\sites\models.py", line 61, in get_current
    return self._get_site_by_request(request)
  File "D:\work\clients_2023\senv\lib\site-packages\django\contrib\sites\models.py", line 45, in _get_site_by_request
    SITE_CACHE[domain] = self.get(domain__iexact=domain)
  File "D:\work\clients_2023\senv\lib\site-packages\django\db\models\manager.py", line 85, in manager_method
    return getattr(self.get_queryset(), name)(*args, **kwargs)
  File "D:\work\clients_2023\senv\lib\site-packages\django\db\models\query.py", line 650, in get
    raise self.model.DoesNotExist(
django.contrib.sites.models.Site.DoesNotExist: Site matching query does not exist.
"GET /sitemap.xml HTTP/1.1" 500 108786
Internal Server Error: /sitemap.xml
Traceback (most recent call last):
  File "D:\work\clients_2023\senv\lib\site-packages\django\contrib\sites\models.py", line 39, in _get_site_by_request
    SITE_CACHE[host] = self.get(domain__iexact=host)
  File "D:\work\clients_2023\senv\lib\site-packages\django\db\models\manager.py", line 85, in manager_method
    return getattr(self.get_queryset(), name)(*args, **kwargs)
  File "D:\work\clients_2023\senv\lib\site-packages\django\db\models\query.py", line 650, in get
    raise self.model.DoesNotExist(
django.contrib.sites.models.Site.DoesNotExist: Site matching query does not exist.

During handling of the above exception, another exception occurred:

Traceback (most recent call last):
  File "D:\work\clients_2023\senv\lib\site-packages\django\core\handlers\exception.py", line 56, in inner
    response = get_response(request)
  File "D:\work\clients_2023\senv\lib\site-packages\django\core\handlers\base.py", line 197, in _get_response
    response = wrapped_callback(request, *callback_args, **callback_kwargs)
  File "D:\work\clients_2023\senv\lib\site-packages\django\contrib\sitemaps\views.py", line 34, in inner
    response = func(request, *args, **kwargs)
  File "D:\work\clients_2023\senv\lib\site-packages\django\contrib\sitemaps\views.py", line 111, in sitemap
    req_site = get_current_site(request)
  File "D:\work\clients_2023\senv\lib\site-packages\django\contrib\sites\shortcuts.py", line 16, in get_current_site
    return Site.objects.get_current(request)
  File "D:\work\clients_2023\senv\lib\site-packages\django\contrib\sites\models.py", line 61, in get_current
    return self._get_site_by_request(request)
  File "D:\work\clients_2023\senv\lib\site-packages\django\contrib\sites\models.py", line 45, in _get_site_by_request
    SITE_CACHE[domain] = self.get(domain__iexact=domain)
  File "D:\work\clients_2023\senv\lib\site-packages\django\db\models\manager.py", line 85, in manager_method
    return getattr(self.get_queryset(), name)(*args, **kwargs)
  File "D:\work\clients_2023\senv\lib\site-packages\django\db\models\query.py", line 650, in get
    raise self.model.DoesNotExist(
django.contrib.sites.models.Site.DoesNotExist: Site matching query does not exist.
"GET /sitemap.xml HTTP/1.1" 500 108786
Internal Server Error: /admin/login/
Traceback (most recent call last):
  File "D:\work\clients_2023\senv\lib\site-packages\django\contrib\sites\models.py", line 39, in _get_site_by_request
    SITE_CACHE[host] = self.get(domain__iexact=host)
  File "D:\work\clients_2023\senv\lib\site-packages\django\db\models\manager.py", line 85, in manager_method
    return getattr(self.get_queryset(), name)(*args, **kwargs)
  File "D:\work\clients_2023\senv\lib\site-packages\django\db\models\query.py", line 650, in get
    raise self.model.DoesNotExist(
django.contrib.sites.models.Site.DoesNotExist: Site matching query does not exist.

During handling of the above exception, another exception occurred:

Traceback (most recent call last):
  File "D:\work\clients_2023\senv\lib\site-packages\django\core\handlers\exception.py", line 56, in inner
    response = get_response(request)
  File "D:\work\clients_2023\senv\lib\site-packages\django\core\handlers\base.py", line 197, in _get_response
    response = wrapped_callback(request, *callback_args, **callback_kwargs)
  File "D:\work\clients_2023\senv\lib\site-packages\django\utils\decorators.py", line 46, in _wrapper
    return bound_method(*args, **kwargs)
  File "D:\work\clients_2023\senv\lib\site-packages\django\views\decorators\cache.py", line 62, in _wrapped_view_func
    response = view_func(request, *args, **kwargs)
  File "D:\work\clients_2023\senv\lib\site-packages\django\contrib\admin\sites.py", line 441, in login
    return LoginView.as_view(**defaults)(request)
  File "D:\work\clients_2023\senv\lib\site-packages\django\views\generic\base.py", line 103, in view
    return self.dispatch(request, *args, **kwargs)
  File "D:\work\clients_2023\senv\lib\site-packages\django\utils\decorators.py", line 46, in _wrapper
    return bound_method(*args, **kwargs)
  File "D:\work\clients_2023\senv\lib\site-packages\django\views\decorators\debug.py", line 92, in sensitive_post_parameters_wrapper
    return view(request, *args, **kwargs)
  File "D:\work\clients_2023\senv\lib\site-packages\django\utils\decorators.py", line 46, in _wrapper
    return bound_method(*args, **kwargs)
  File "D:\work\clients_2023\senv\lib\site-packages\django\utils\decorators.py", line 134, in _wrapped_view
    response = view_func(request, *args, **kwargs)
  File "D:\work\clients_2023\senv\lib\site-packages\django\utils\decorators.py", line 46, in _wrapper
    return bound_method(*args, **kwargs)
  File "D:\work\clients_2023\senv\lib\site-packages\django\views\decorators\cache.py", line 62, in _wrapped_view_func
    response = view_func(request, *args, **kwargs)
  File "D:\work\clients_2023\senv\lib\site-packages\django\contrib\auth\views.py", line 90, in dispatch
    return super().dispatch(request, *args, **kwargs)
  File "D:\work\clients_2023\senv\lib\site-packages\django\views\generic\base.py", line 142, in dispatch
    return handler(request, *args, **kwargs)
  File "D:\work\clients_2023\senv\lib\site-packages\django\views\generic\edit.py", line 144, in get
    return self.render_to_response(self.get_context_data())
  File "D:\work\clients_2023\senv\lib\site-packages\django\contrib\auth\views.py", line 114, in get_context_data
    current_site = get_current_site(self.request)
  File "D:\work\clients_2023\senv\lib\site-packages\django\contrib\sites\shortcuts.py", line 16, in get_current_site
    return Site.objects.get_current(request)
  File "D:\work\clients_2023\senv\lib\site-packages\django\contrib\sites\models.py", line 61, in get_current
    return self._get_site_by_request(request)
  File "D:\work\clients_2023\senv\lib\site-packages\django\contrib\sites\models.py", line 45, in _get_site_by_request
    SITE_CACHE[domain] = self.get(domain__iexact=domain)
  File "D:\work\clients_2023\senv\lib\site-packages\django\db\models\manager.py", line 85, in manager_method
    return getattr(self.get_queryset(), name)(*args, **kwargs)
  File "D:\work\clients_2023\senv\lib\site-packages\django\db\models\query.py", line 650, in get
    raise self.model.DoesNotExist(
django.contrib.sites.models.Site.DoesNotExist: Site matching query does not exist.
"GET /admin/login/?next=/admin/ HTTP/1.1" 500 167730
Internal Server Error: /admin/login/
Traceback (most recent call last):
  File "D:\work\clients_2023\senv\lib\site-packages\django\db\backends\utils.py", line 89, in _execute
    return self.cursor.execute(sql, params)
  File "D:\work\clients_2023\senv\lib\site-packages\django\db\backends\mysql\base.py", line 75, in execute
    return self.cursor.execute(query, args)
  File "D:\work\clients_2023\senv\lib\site-packages\MySQLdb\cursors.py", line 206, in execute
    res = self._query(query)
  File "D:\work\clients_2023\senv\lib\site-packages\MySQLdb\cursors.py", line 319, in _query
    db.query(q)
  File "D:\work\clients_2023\senv\lib\site-packages\MySQLdb\connections.py", line 254, in query
    _mysql.connection.query(self, query)
MySQLdb.ProgrammingError: (1146, "Table 'civils.django_site' doesn't exist")

The above exception was the direct cause of the following exception:

Traceback (most recent call last):
  File "D:\work\clients_2023\senv\lib\site-packages\django\core\handlers\exception.py", line 56, in inner
    response = get_response(request)
  File "D:\work\clients_2023\senv\lib\site-packages\django\core\handlers\base.py", line 197, in _get_response
    response = wrapped_callback(request, *callback_args, **callback_kwargs)
  File "D:\work\clients_2023\senv\lib\site-packages\django\utils\decorators.py", line 46, in _wrapper
    return bound_method(*args, **kwargs)
  File "D:\work\clients_2023\senv\lib\site-packages\django\views\decorators\cache.py", line 62, in _wrapped_view_func
    response = view_func(request, *args, **kwargs)
  File "D:\work\clients_2023\senv\lib\site-packages\django\contrib\admin\sites.py", line 441, in login
    return LoginView.as_view(**defaults)(request)
  File "D:\work\clients_2023\senv\lib\site-packages\django\views\generic\base.py", line 103, in view
    return self.dispatch(request, *args, **kwargs)
  File "D:\work\clients_2023\senv\lib\site-packages\django\utils\decorators.py", line 46, in _wrapper
    return bound_method(*args, **kwargs)
  File "D:\work\clients_2023\senv\lib\site-packages\django\views\decorators\debug.py", line 92, in sensitive_post_parameters_wrapper
    return view(request, *args, **kwargs)
  File "D:\work\clients_2023\senv\lib\site-packages\django\utils\decorators.py", line 46, in _wrapper
    return bound_method(*args, **kwargs)
  File "D:\work\clients_2023\senv\lib\site-packages\django\utils\decorators.py", line 134, in _wrapped_view
    response = view_func(request, *args, **kwargs)
  File "D:\work\clients_2023\senv\lib\site-packages\django\utils\decorators.py", line 46, in _wrapper
    return bound_method(*args, **kwargs)
  File "D:\work\clients_2023\senv\lib\site-packages\django\views\decorators\cache.py", line 62, in _wrapped_view_func
    response = view_func(request, *args, **kwargs)
  File "D:\work\clients_2023\senv\lib\site-packages\django\contrib\auth\views.py", line 90, in dispatch
    return super().dispatch(request, *args, **kwargs)
  File "D:\work\clients_2023\senv\lib\site-packages\django\views\generic\base.py", line 142, in dispatch
    return handler(request, *args, **kwargs)
  File "D:\work\clients_2023\senv\lib\site-packages\django\views\generic\edit.py", line 144, in get
    return self.render_to_response(self.get_context_data())
  File "D:\work\clients_2023\senv\lib\site-packages\django\contrib\auth\views.py", line 114, in get_context_data
    current_site = get_current_site(self.request)
  File "D:\work\clients_2023\senv\lib\site-packages\django\contrib\sites\shortcuts.py", line 16, in get_current_site
    return Site.objects.get_current(request)
  File "D:\work\clients_2023\senv\lib\site-packages\django\contrib\sites\models.py", line 61, in get_current
    return self._get_site_by_request(request)
  File "D:\work\clients_2023\senv\lib\site-packages\django\contrib\sites\models.py", line 39, in _get_site_by_request
    SITE_CACHE[host] = self.get(domain__iexact=host)
  File "D:\work\clients_2023\senv\lib\site-packages\django\db\models\manager.py", line 85, in manager_method
    return getattr(self.get_queryset(), name)(*args, **kwargs)
  File "D:\work\clients_2023\senv\lib\site-packages\django\db\models\query.py", line 646, in get
    num = len(clone)
  File "D:\work\clients_2023\senv\lib\site-packages\django\db\models\query.py", line 376, in __len__
    self._fetch_all()
  File "D:\work\clients_2023\senv\lib\site-packages\django\db\models\query.py", line 1867, in _fetch_all
    self._result_cache = list(self._iterable_class(self))
  File "D:\work\clients_2023\senv\lib\site-packages\django\db\models\query.py", line 87, in __iter__
    results = compiler.execute_sql(
  File "D:\work\clients_2023\senv\lib\site-packages\django\db\models\sql\compiler.py", line 1398, in execute_sql
    cursor.execute(sql, params)
  File "D:\work\clients_2023\senv\lib\site-packages\django\db\backends\utils.py", line 102, in execute
    return super().execute(sql, params)
  File "D:\work\clients_2023\senv\lib\site-packages\django\db\backends\utils.py", line 67, in execute
    return self._execute_with_wrappers(
  File "D:\work\clients_2023\senv\lib\site-packages\django\db\backends\utils.py", line 80, in _execute_with_wrappers
    return executor(sql, params, many, context)
  File "D:\work\clients_2023\senv\lib\site-packages\django\db\backends\utils.py", line 89, in _execute
    return self.cursor.execute(sql, params)
  File "D:\work\clients_2023\senv\lib\site-packages\django\db\utils.py", line 91, in __exit__
    raise dj_exc_value.with_traceback(traceback) from exc_value
  File "D:\work\clients_2023\senv\lib\site-packages\django\db\backends\utils.py", line 89, in _execute
    return self.cursor.execute(sql, params)
  File "D:\work\clients_2023\senv\lib\site-packages\django\db\backends\mysql\base.py", line 75, in execute
    return self.cursor.execute(query, args)
  File "D:\work\clients_2023\senv\lib\site-packages\MySQLdb\cursors.py", line 206, in execute
    res = self._query(query)
  File "D:\work\clients_2023\senv\lib\site-packages\MySQLdb\cursors.py", line 319, in _query
    db.query(q)
  File "D:\work\clients_2023\senv\lib\site-packages\MySQLdb\connections.py", line 254, in query
    _mysql.connection.query(self, query)
django.db.utils.ProgrammingError: (1146, "Table 'civils.django_site' doesn't exist")
"GET /admin/login/?next=/admin/ HTTP/1.1" 500 235950
Internal Server Error: /admin/login/
Traceback (most recent call last):
  File "D:\work\clients_2023\senv\lib\site-packages\django\contrib\sites\models.py", line 39, in _get_site_by_request
    SITE_CACHE[host] = self.get(domain__iexact=host)
  File "D:\work\clients_2023\senv\lib\site-packages\django\db\models\manager.py", line 85, in manager_method
    return getattr(self.get_queryset(), name)(*args, **kwargs)
  File "D:\work\clients_2023\senv\lib\site-packages\django\db\models\query.py", line 650, in get
    raise self.model.DoesNotExist(
django.contrib.sites.models.Site.DoesNotExist: Site matching query does not exist.

During handling of the above exception, another exception occurred:

Traceback (most recent call last):
  File "D:\work\clients_2023\senv\lib\site-packages\django\core\handlers\exception.py", line 56, in inner
    response = get_response(request)
  File "D:\work\clients_2023\senv\lib\site-packages\django\core\handlers\base.py", line 197, in _get_response
    response = wrapped_callback(request, *callback_args, **callback_kwargs)
  File "D:\work\clients_2023\senv\lib\site-packages\django\utils\decorators.py", line 46, in _wrapper
    return bound_method(*args, **kwargs)
  File "D:\work\clients_2023\senv\lib\site-packages\django\views\decorators\cache.py", line 62, in _wrapped_view_func
    response = view_func(request, *args, **kwargs)
  File "D:\work\clients_2023\senv\lib\site-packages\django\contrib\admin\sites.py", line 441, in login
    return LoginView.as_view(**defaults)(request)
  File "D:\work\clients_2023\senv\lib\site-packages\django\views\generic\base.py", line 103, in view
    return self.dispatch(request, *args, **kwargs)
  File "D:\work\clients_2023\senv\lib\site-packages\django\utils\decorators.py", line 46, in _wrapper
    return bound_method(*args, **kwargs)
  File "D:\work\clients_2023\senv\lib\site-packages\django\views\decorators\debug.py", line 92, in sensitive_post_parameters_wrapper
    return view(request, *args, **kwargs)
  File "D:\work\clients_2023\senv\lib\site-packages\django\utils\decorators.py", line 46, in _wrapper
    return bound_method(*args, **kwargs)
  File "D:\work\clients_2023\senv\lib\site-packages\django\utils\decorators.py", line 134, in _wrapped_view
    response = view_func(request, *args, **kwargs)
  File "D:\work\clients_2023\senv\lib\site-packages\django\utils\decorators.py", line 46, in _wrapper
    return bound_method(*args, **kwargs)
  File "D:\work\clients_2023\senv\lib\site-packages\django\views\decorators\cache.py", line 62, in _wrapped_view_func
    response = view_func(request, *args, **kwargs)
  File "D:\work\clients_2023\senv\lib\site-packages\django\contrib\auth\views.py", line 90, in dispatch
    return super().dispatch(request, *args, **kwargs)
  File "D:\work\clients_2023\senv\lib\site-packages\django\views\generic\base.py", line 142, in dispatch
    return handler(request, *args, **kwargs)
  File "D:\work\clients_2023\senv\lib\site-packages\django\views\generic\edit.py", line 144, in get
    return self.render_to_response(self.get_context_data())
  File "D:\work\clients_2023\senv\lib\site-packages\django\contrib\auth\views.py", line 114, in get_context_data
    current_site = get_current_site(self.request)
  File "D:\work\clients_2023\senv\lib\site-packages\django\contrib\sites\shortcuts.py", line 16, in get_current_site
    return Site.objects.get_current(request)
  File "D:\work\clients_2023\senv\lib\site-packages\django\contrib\sites\models.py", line 61, in get_current
    return self._get_site_by_request(request)
  File "D:\work\clients_2023\senv\lib\site-packages\django\contrib\sites\models.py", line 45, in _get_site_by_request
    SITE_CACHE[domain] = self.get(domain__iexact=domain)
  File "D:\work\clients_2023\senv\lib\site-packages\django\db\models\manager.py", line 85, in manager_method
    return getattr(self.get_queryset(), name)(*args, **kwargs)
  File "D:\work\clients_2023\senv\lib\site-packages\django\db\models\query.py", line 650, in get
    raise self.model.DoesNotExist(
django.contrib.sites.models.Site.DoesNotExist: Site matching query does not exist.
"GET /admin/login/?next=/admin/ HTTP/1.1" 500 167891
Internal Server Error: /
Traceback (most recent call last):
  File "D:\work\clients_2023\senv\lib\site-packages\django\core\handlers\exception.py", line 56, in inner
    response = get_response(request)
  File "D:\work\clients_2023\senv\lib\site-packages\django\core\handlers\base.py", line 197, in _get_response
    response = wrapped_callback(request, *callback_args, **callback_kwargs)
  File "D:\work\clients_2023\webcivils\views.py", line 6, in home
    return render(request, 'home.html', context)
  File "D:\work\clients_2023\senv\lib\site-packages\django\shortcuts.py", line 24, in render
    content = loader.render_to_string(template_name, context, request, using=using)
  File "D:\work\clients_2023\senv\lib\site-packages\django\template\loader.py", line 61, in render_to_string
    template = get_template(template_name, using=using)
  File "D:\work\clients_2023\senv\lib\site-packages\django\template\loader.py", line 19, in get_template
    raise TemplateDoesNotExist(template_name, chain=chain)
django.template.exceptions.TemplateDoesNotExist: home.html
"GET / HTTP/1.1" 500 83807
Internal Server Error: /
Traceback (most recent call last):
  File "D:\work\clients_2023\senv\lib\site-packages\django\core\handlers\exception.py", line 56, in inner
    response = get_response(request)
  File "D:\work\clients_2023\senv\lib\site-packages\django\core\handlers\base.py", line 197, in _get_response
    response = wrapped_callback(request, *callback_args, **callback_kwargs)
  File "D:\work\clients_2023\webcivils\views.py", line 6, in home
    return render(request, 'home.html', context)
  File "D:\work\clients_2023\senv\lib\site-packages\django\shortcuts.py", line 24, in render
    content = loader.render_to_string(template_name, context, request, using=using)
  File "D:\work\clients_2023\senv\lib\site-packages\django\template\loader.py", line 61, in render_to_string
    template = get_template(template_name, using=using)
  File "D:\work\clients_2023\senv\lib\site-packages\django\template\loader.py", line 19, in get_template
    raise TemplateDoesNotExist(template_name, chain=chain)
django.template.exceptions.TemplateDoesNotExist: home.html
"GET / HTTP/1.1" 500 84120
Internal Server Error: /
Traceback (most recent call last):
  File "D:\work\clients_2023\senv\lib\site-packages\django\core\handlers\exception.py", line 56, in inner
    response = get_response(request)
  File "D:\work\clients_2023\senv\lib\site-packages\django\core\handlers\base.py", line 197, in _get_response
    response = wrapped_callback(request, *callback_args, **callback_kwargs)
  File "D:\work\clients_2023\webcivils\views.py", line 6, in home
    return render(request, 'home.html', context)
  File "D:\work\clients_2023\senv\lib\site-packages\django\shortcuts.py", line 24, in render
    content = loader.render_to_string(template_name, context, request, using=using)
  File "D:\work\clients_2023\senv\lib\site-packages\django\template\loader.py", line 62, in render_to_string
    return template.render(context, request)
  File "D:\work\clients_2023\senv\lib\site-packages\django\template\backends\django.py", line 61, in render
    return self.template.render(context)
  File "D:\work\clients_2023\senv\lib\site-packages\django\template\base.py", line 175, in render
    return self._render(context)
  File "D:\work\clients_2023\senv\lib\site-packages\django\template\base.py", line 167, in _render
    return self.nodelist.render(context)
  File "D:\work\clients_2023\senv\lib\site-packages\django\template\base.py", line 1005, in render
    return SafeString("".join([node.render_annotated(context) for node in self]))
  File "D:\work\clients_2023\senv\lib\site-packages\django\template\base.py", line 1005, in <listcomp>
    return SafeString("".join([node.render_annotated(context) for node in self]))
  File "D:\work\clients_2023\senv\lib\site-packages\django\template\base.py", line 966, in render_annotated
    return self.render(context)
  File "D:\work\clients_2023\senv\lib\site-packages\django\template\loader_tags.py", line 132, in render
    compiled_parent = self.get_parent(context)
  File "D:\work\clients_2023\senv\lib\site-packages\django\template\loader_tags.py", line 129, in get_parent
    return self.find_template(parent, context)
  File "D:\work\clients_2023\senv\lib\site-packages\django\template\loader_tags.py", line 107, in find_template
    template, origin = context.template.engine.find_template(
  File "D:\work\clients_2023\senv\lib\site-packages\django\template\engine.py", line 157, in find_template
    template = loader.get_template(name, skip=skip)
  File "D:\work\clients_2023\senv\lib\site-packages\django\template\loaders\cached.py", line 57, in get_template
    template = super().get_template(template_name, skip)
  File "D:\work\clients_2023\senv\lib\site-packages\django\template\loaders\base.py", line 28, in get_template
    return Template(
  File "D:\work\clients_2023\senv\lib\site-packages\django\template\base.py", line 154, in __init__
    self.nodelist = self.compile_nodelist()
  File "D:\work\clients_2023\senv\lib\site-packages\django\template\base.py", line 200, in compile_nodelist
    return parser.parse()
  File "D:\work\clients_2023\senv\lib\site-packages\django\template\base.py", line 513, in parse
    raise self.error(token, e)
  File "D:\work\clients_2023\senv\lib\site-packages\django\template\base.py", line 511, in parse
    compiled_result = compile_func(self, token)
  File "D:\work\clients_2023\senv\lib\site-packages\django\template\defaulttags.py", line 952, in do_if
    condition = TemplateIfParser(parser, bits).parse()
  File "D:\work\clients_2023\senv\lib\site-packages\django\template\smartif.py", line 194, in parse
    retval = self.expression()
  File "D:\work\clients_2023\senv\lib\site-packages\django\template\smartif.py", line 205, in expression
    left = t.nud(self)
  File "D:\work\clients_2023\senv\lib\site-packages\django\template\smartif.py", line 148, in nud
    raise parser.error_class("Unexpected end of expression in if tag.")
django.template.exceptions.TemplateSyntaxError: Unexpected end of expression in if tag.
"GET / HTTP/1.1" 500 186338
Internal Server Error: /
Traceback (most recent call last):
  File "D:\work\clients_2023\senv\lib\site-packages\django\template\base.py", line 505, in parse
    compile_func = self.tags[command]
KeyError: 'static'

During handling of the above exception, another exception occurred:

Traceback (most recent call last):
  File "D:\work\clients_2023\senv\lib\site-packages\django\core\handlers\exception.py", line 56, in inner
    response = get_response(request)
  File "D:\work\clients_2023\senv\lib\site-packages\django\core\handlers\base.py", line 197, in _get_response
    response = wrapped_callback(request, *callback_args, **callback_kwargs)
  File "D:\work\clients_2023\webcivils\views.py", line 6, in home
    return render(request, 'home.html', context)
  File "D:\work\clients_2023\senv\lib\site-packages\django\shortcuts.py", line 24, in render
    content = loader.render_to_string(template_name, context, request, using=using)
  File "D:\work\clients_2023\senv\lib\site-packages\django\template\loader.py", line 62, in render_to_string
    return template.render(context, request)
  File "D:\work\clients_2023\senv\lib\site-packages\django\template\backends\django.py", line 61, in render
    return self.template.render(context)
  File "D:\work\clients_2023\senv\lib\site-packages\django\template\base.py", line 175, in render
    return self._render(context)
  File "D:\work\clients_2023\senv\lib\site-packages\django\template\base.py", line 167, in _render
    return self.nodelist.render(context)
  File "D:\work\clients_2023\senv\lib\site-packages\django\template\base.py", line 1005, in render
    return SafeString("".join([node.render_annotated(context) for node in self]))
  File "D:\work\clients_2023\senv\lib\site-packages\django\template\base.py", line 1005, in <listcomp>
    return SafeString("".join([node.render_annotated(context) for node in self]))
  File "D:\work\clients_2023\senv\lib\site-packages\django\template\base.py", line 966, in render_annotated
    return self.render(context)
  File "D:\work\clients_2023\senv\lib\site-packages\django\template\loader_tags.py", line 132, in render
    compiled_parent = self.get_parent(context)
  File "D:\work\clients_2023\senv\lib\site-packages\django\template\loader_tags.py", line 129, in get_parent
    return self.find_template(parent, context)
  File "D:\work\clients_2023\senv\lib\site-packages\django\template\loader_tags.py", line 107, in find_template
    template, origin = context.template.engine.find_template(
  File "D:\work\clients_2023\senv\lib\site-packages\django\template\engine.py", line 157, in find_template
    template = loader.get_template(name, skip=skip)
  File "D:\work\clients_2023\senv\lib\site-packages\django\template\loaders\cached.py", line 57, in get_template
    template = super().get_template(template_name, skip)
  File "D:\work\clients_2023\senv\lib\site-packages\django\template\loaders\base.py", line 28, in get_template
    return Template(
  File "D:\work\clients_2023\senv\lib\site-packages\django\template\base.py", line 154, in __init__
    self.nodelist = self.compile_nodelist()
  File "D:\work\clients_2023\senv\lib\site-packages\django\template\base.py", line 200, in compile_nodelist
    return parser.parse()
  File "D:\work\clients_2023\senv\lib\site-packages\django\template\base.py", line 507, in parse
    self.invalid_block_tag(token, command, parse_until)
  File "D:\work\clients_2023\senv\lib\site-packages\django\template\base.py", line 568, in invalid_block_tag
    raise self.error(
django.template.exceptions.TemplateSyntaxError: Invalid block tag on line 1045: 'static'. Did you forget to register or load this tag?
"GET / HTTP/1.1" 500 176370
Internal Server Error: /
Traceback (most recent call last):
  File "D:\work\clients_2023\senv\lib\site-packages\django\template\base.py", line 505, in parse
    compile_func = self.tags[command]
KeyError: 'static'

During handling of the above exception, another exception occurred:

Traceback (most recent call last):
  File "D:\work\clients_2023\senv\lib\site-packages\django\core\handlers\exception.py", line 56, in inner
    response = get_response(request)
  File "D:\work\clients_2023\senv\lib\site-packages\django\core\handlers\base.py", line 197, in _get_response
    response = wrapped_callback(request, *callback_args, **callback_kwargs)
  File "D:\work\clients_2023\webcivils\views.py", line 6, in home
    return render(request, 'home.html', context)
  File "D:\work\clients_2023\senv\lib\site-packages\django\shortcuts.py", line 24, in render
    content = loader.render_to_string(template_name, context, request, using=using)
  File "D:\work\clients_2023\senv\lib\site-packages\django\template\loader.py", line 62, in render_to_string
    return template.render(context, request)
  File "D:\work\clients_2023\senv\lib\site-packages\django\template\backends\django.py", line 61, in render
    return self.template.render(context)
  File "D:\work\clients_2023\senv\lib\site-packages\django\template\base.py", line 175, in render
    return self._render(context)
  File "D:\work\clients_2023\senv\lib\site-packages\django\template\base.py", line 167, in _render
    return self.nodelist.render(context)
  File "D:\work\clients_2023\senv\lib\site-packages\django\template\base.py", line 1005, in render
    return SafeString("".join([node.render_annotated(context) for node in self]))
  File "D:\work\clients_2023\senv\lib\site-packages\django\template\base.py", line 1005, in <listcomp>
    return SafeString("".join([node.render_annotated(context) for node in self]))
  File "D:\work\clients_2023\senv\lib\site-packages\django\template\base.py", line 966, in render_annotated
    return self.render(context)
  File "D:\work\clients_2023\senv\lib\site-packages\django\template\loader_tags.py", line 132, in render
    compiled_parent = self.get_parent(context)
  File "D:\work\clients_2023\senv\lib\site-packages\django\template\loader_tags.py", line 129, in get_parent
    return self.find_template(parent, context)
  File "D:\work\clients_2023\senv\lib\site-packages\django\template\loader_tags.py", line 107, in find_template
    template, origin = context.template.engine.find_template(
  File "D:\work\clients_2023\senv\lib\site-packages\django\template\engine.py", line 157, in find_template
    template = loader.get_template(name, skip=skip)
  File "D:\work\clients_2023\senv\lib\site-packages\django\template\loaders\cached.py", line 57, in get_template
    template = super().get_template(template_name, skip)
  File "D:\work\clients_2023\senv\lib\site-packages\django\template\loaders\base.py", line 28, in get_template
    return Template(
  File "D:\work\clients_2023\senv\lib\site-packages\django\template\base.py", line 154, in __init__
    self.nodelist = self.compile_nodelist()
  File "D:\work\clients_2023\senv\lib\site-packages\django\template\base.py", line 200, in compile_nodelist
    return parser.parse()
  File "D:\work\clients_2023\senv\lib\site-packages\django\template\base.py", line 507, in parse
    self.invalid_block_tag(token, command, parse_until)
  File "D:\work\clients_2023\senv\lib\site-packages\django\template\base.py", line 568, in invalid_block_tag
    raise self.error(
django.template.exceptions.TemplateSyntaxError: Invalid block tag on line 28: 'static'. Did you forget to register or load this tag?
"GET / HTTP/1.1" 500 182217
Internal Server Error: /services
Traceback (most recent call last):
  File "D:\work\clients_2023\senv\lib\site-packages\django\core\handlers\exception.py", line 56, in inner
    response = get_response(request)
  File "D:\work\clients_2023\senv\lib\site-packages\django\core\handlers\base.py", line 197, in _get_response
    response = wrapped_callback(request, *callback_args, **callback_kwargs)
  File "D:\work\clients_2023\webcivils\views.py", line 22, in services
    return render(request, 'services.html', context)
  File "D:\work\clients_2023\senv\lib\site-packages\django\shortcuts.py", line 24, in render
    content = loader.render_to_string(template_name, context, request, using=using)
  File "D:\work\clients_2023\senv\lib\site-packages\django\template\loader.py", line 61, in render_to_string
    template = get_template(template_name, using=using)
  File "D:\work\clients_2023\senv\lib\site-packages\django\template\loader.py", line 19, in get_template
    raise TemplateDoesNotExist(template_name, chain=chain)
django.template.exceptions.TemplateDoesNotExist: services.html
"GET /services HTTP/1.1" 500 83646
Internal Server Error: /contact
Traceback (most recent call last):
  File "D:\work\clients_2023\senv\lib\site-packages\django\core\handlers\exception.py", line 56, in inner
    response = get_response(request)
  File "D:\work\clients_2023\senv\lib\site-packages\django\core\handlers\base.py", line 197, in _get_response
    response = wrapped_callback(request, *callback_args, **callback_kwargs)
  File "D:\work\clients_2023\webcivils\views.py", line 20, in contact
    form = ContactForm(request.POST, None)
  File "D:\work\clients_2023\senv\lib\site-packages\django\forms\models.py", line 356, in __init__
    raise ValueError("ModelForm has no model class specified.")
ValueError: ModelForm has no model class specified.
"GET /contact HTTP/1.1" 500 75853
Internal Server Error: /contact
Traceback (most recent call last):
  File "D:\work\clients_2023\senv\lib\site-packages\django\db\backends\utils.py", line 89, in _execute
    return self.cursor.execute(sql, params)
  File "D:\work\clients_2023\senv\lib\site-packages\django\db\backends\mysql\base.py", line 75, in execute
    return self.cursor.execute(query, args)
  File "D:\work\clients_2023\senv\lib\site-packages\MySQLdb\cursors.py", line 206, in execute
    res = self._query(query)
  File "D:\work\clients_2023\senv\lib\site-packages\MySQLdb\cursors.py", line 319, in _query
    db.query(q)
  File "D:\work\clients_2023\senv\lib\site-packages\MySQLdb\connections.py", line 254, in query
    _mysql.connection.query(self, query)
MySQLdb.ProgrammingError: (1146, "Table 'civils.support_contact' doesn't exist")

The above exception was the direct cause of the following exception:

Traceback (most recent call last):
  File "D:\work\clients_2023\senv\lib\site-packages\django\core\handlers\exception.py", line 56, in inner
    response = get_response(request)
  File "D:\work\clients_2023\senv\lib\site-packages\django\core\handlers\base.py", line 197, in _get_response
    response = wrapped_callback(request, *callback_args, **callback_kwargs)
  File "D:\work\clients_2023\webcivils\views.py", line 23, in contact
    form.save()
  File "D:\work\clients_2023\senv\lib\site-packages\django\forms\models.py", line 548, in save
    self.instance.save()
  File "D:\work\clients_2023\senv\lib\site-packages\django\db\models\base.py", line 812, in save
    self.save_base(
  File "D:\work\clients_2023\senv\lib\site-packages\django\db\models\base.py", line 863, in save_base
    updated = self._save_table(
  File "D:\work\clients_2023\senv\lib\site-packages\django\db\models\base.py", line 1006, in _save_table
    results = self._do_insert(
  File "D:\work\clients_2023\senv\lib\site-packages\django\db\models\base.py", line 1047, in _do_insert
    return manager._insert(
  File "D:\work\clients_2023\senv\lib\site-packages\django\db\models\manager.py", line 85, in manager_method
    return getattr(self.get_queryset(), name)(*args, **kwargs)
  File "D:\work\clients_2023\senv\lib\site-packages\django\db\models\query.py", line 1791, in _insert
    return query.get_compiler(using=using).execute_sql(returning_fields)
  File "D:\work\clients_2023\senv\lib\site-packages\django\db\models\sql\compiler.py", line 1660, in execute_sql
    cursor.execute(sql, params)
  File "D:\work\clients_2023\senv\lib\site-packages\django\db\backends\utils.py", line 102, in execute
    return super().execute(sql, params)
  File "D:\work\clients_2023\senv\lib\site-packages\django\db\backends\utils.py", line 67, in execute
    return self._execute_with_wrappers(
  File "D:\work\clients_2023\senv\lib\site-packages\django\db\backends\utils.py", line 80, in _execute_with_wrappers
    return executor(sql, params, many, context)
  File "D:\work\clients_2023\senv\lib\site-packages\django\db\backends\utils.py", line 89, in _execute
    return self.cursor.execute(sql, params)
  File "D:\work\clients_2023\senv\lib\site-packages\django\db\utils.py", line 91, in __exit__
    raise dj_exc_value.with_traceback(traceback) from exc_value
  File "D:\work\clients_2023\senv\lib\site-packages\django\db\backends\utils.py", line 89, in _execute
    return self.cursor.execute(sql, params)
  File "D:\work\clients_2023\senv\lib\site-packages\django\db\backends\mysql\base.py", line 75, in execute
    return self.cursor.execute(query, args)
  File "D:\work\clients_2023\senv\lib\site-packages\MySQLdb\cursors.py", line 206, in execute
    res = self._query(query)
  File "D:\work\clients_2023\senv\lib\site-packages\MySQLdb\cursors.py", line 319, in _query
    db.query(q)
  File "D:\work\clients_2023\senv\lib\site-packages\MySQLdb\connections.py", line 254, in query
    _mysql.connection.query(self, query)
django.db.utils.ProgrammingError: (1146, "Table 'civils.support_contact' doesn't exist")
"POST /contact HTTP/1.1" 500 180449
Internal Server Error: /services
Traceback (most recent call last):
  File "D:\work\clients_2023\senv\lib\site-packages\django\core\handlers\exception.py", line 56, in inner
    response = get_response(request)
  File "D:\work\clients_2023\senv\lib\site-packages\django\core\handlers\base.py", line 197, in _get_response
    response = wrapped_callback(request, *callback_args, **callback_kwargs)
  File "D:\work\clients_2023\webcivils\views.py", line 31, in services
    return render(request, 'services.html', context)
  File "D:\work\clients_2023\senv\lib\site-packages\django\shortcuts.py", line 24, in render
    content = loader.render_to_string(template_name, context, request, using=using)
  File "D:\work\clients_2023\senv\lib\site-packages\django\template\loader.py", line 61, in render_to_string
    template = get_template(template_name, using=using)
  File "D:\work\clients_2023\senv\lib\site-packages\django\template\loader.py", line 19, in get_template
    raise TemplateDoesNotExist(template_name, chain=chain)
django.template.exceptions.TemplateDoesNotExist: services.html
"GET /services HTTP/1.1" 500 83581
Internal Server Error: /
Traceback (most recent call last):
  File "D:\work\clients_2023\senv\lib\site-packages\django\core\handlers\exception.py", line 56, in inner
    response = get_response(request)
  File "D:\work\clients_2023\senv\lib\site-packages\django\core\handlers\base.py", line 197, in _get_response
    response = wrapped_callback(request, *callback_args, **callback_kwargs)
  File "D:\work\clients_2023\webcivils\views.py", line 8, in home
    contact['title'] = 'TLB Hire Gauteng. Best Price TLB Hire'
TypeError: 'function' object does not support item assignment
"GET / HTTP/1.1" 500 69716
Internal Server Error: /1/ghh
Traceback (most recent call last):
  File "D:\work\clients_2023\senv\lib\site-packages\django\core\handlers\exception.py", line 56, in inner
    response = get_response(request)
  File "D:\work\clients_2023\senv\lib\site-packages\django\core\handlers\base.py", line 197, in _get_response
    response = wrapped_callback(request, *callback_args, **callback_kwargs)
TypeError: service() got an unexpected keyword argument 'pk'
"GET /1/ghh HTTP/1.1" 500 66903
Internal Server Error: /1/ghh
Traceback (most recent call last):
  File "D:\work\clients_2023\senv\lib\site-packages\django\core\handlers\exception.py", line 56, in inner
    response = get_response(request)
  File "D:\work\clients_2023\senv\lib\site-packages\django\core\handlers\base.py", line 197, in _get_response
    response = wrapped_callback(request, *callback_args, **callback_kwargs)
TypeError: service() got an unexpected keyword argument 'slug'
"GET /1/ghh HTTP/1.1" 500 66829
Internal Server Error: /1/serv
Traceback (most recent call last):
  File "D:\work\clients_2023\senv\lib\site-packages\django\core\handlers\exception.py", line 56, in inner
    response = get_response(request)
  File "D:\work\clients_2023\senv\lib\site-packages\django\core\handlers\base.py", line 197, in _get_response
    response = wrapped_callback(request, *callback_args, **callback_kwargs)
  File "D:\work\clients_2023\support\views.py", line 14, in service
    return render(request, 'service.html', context)
  File "D:\work\clients_2023\senv\lib\site-packages\django\shortcuts.py", line 24, in render
    content = loader.render_to_string(template_name, context, request, using=using)
  File "D:\work\clients_2023\senv\lib\site-packages\django\template\loader.py", line 62, in render_to_string
    return template.render(context, request)
  File "D:\work\clients_2023\senv\lib\site-packages\django\template\backends\django.py", line 61, in render
    return self.template.render(context)
  File "D:\work\clients_2023\senv\lib\site-packages\django\template\base.py", line 175, in render
    return self._render(context)
  File "D:\work\clients_2023\senv\lib\site-packages\django\template\base.py", line 167, in _render
    return self.nodelist.render(context)
  File "D:\work\clients_2023\senv\lib\site-packages\django\template\base.py", line 1005, in render
    return SafeString("".join([node.render_annotated(context) for node in self]))
  File "D:\work\clients_2023\senv\lib\site-packages\django\template\base.py", line 1005, in <listcomp>
    return SafeString("".join([node.render_annotated(context) for node in self]))
  File "D:\work\clients_2023\senv\lib\site-packages\django\template\base.py", line 966, in render_annotated
    return self.render(context)
  File "D:\work\clients_2023\senv\lib\site-packages\django\template\loader_tags.py", line 157, in render
    return compiled_parent._render(context)
  File "D:\work\clients_2023\senv\lib\site-packages\django\template\base.py", line 167, in _render
    return self.nodelist.render(context)
  File "D:\work\clients_2023\senv\lib\site-packages\django\template\base.py", line 1005, in render
    return SafeString("".join([node.render_annotated(context) for node in self]))
  File "D:\work\clients_2023\senv\lib\site-packages\django\template\base.py", line 1005, in <listcomp>
    return SafeString("".join([node.render_annotated(context) for node in self]))
  File "D:\work\clients_2023\senv\lib\site-packages\django\template\base.py", line 966, in render_annotated
    return self.render(context)
  File "D:\work\clients_2023\senv\lib\site-packages\django\template\loader_tags.py", line 63, in render
    result = block.nodelist.render(context)
  File "D:\work\clients_2023\senv\lib\site-packages\django\template\base.py", line 1005, in render
    return SafeString("".join([node.render_annotated(context) for node in self]))
  File "D:\work\clients_2023\senv\lib\site-packages\django\template\base.py", line 1005, in <listcomp>
    return SafeString("".join([node.render_annotated(context) for node in self]))
  File "D:\work\clients_2023\senv\lib\site-packages\django\template\base.py", line 966, in render_annotated
    return self.render(context)
  File "D:\work\clients_2023\senv\lib\site-packages\django\template\base.py", line 1064, in render
    output = self.filter_expression.resolve(context)
  File "D:\work\clients_2023\senv\lib\site-packages\django\template\base.py", line 715, in resolve
    obj = self.var.resolve(context)
  File "D:\work\clients_2023\senv\lib\site-packages\django\template\base.py", line 847, in resolve
    value = self._resolve_lookup(context)
  File "D:\work\clients_2023\senv\lib\site-packages\django\template\base.py", line 914, in _resolve_lookup
    current = current()
  File "D:\work\clients_2023\support\models.py", line 45, in get_absolute_url
    return reverse('service', kwargs={'pk': self.pk, 'slug': self.slug})
  File "D:\work\clients_2023\senv\lib\site-packages\django\urls\base.py", line 88, in reverse
    return resolver._reverse_with_prefix(view, prefix, *args, **kwargs)
  File "D:\work\clients_2023\senv\lib\site-packages\django\urls\resolvers.py", line 828, in _reverse_with_prefix
    raise NoReverseMatch(msg)
django.urls.exceptions.NoReverseMatch: Reverse for 'service' with keyword arguments '{'pk': 1, 'slug': 'temporibus-et-in-vero-dicta-aut-eius-lidero-plastis-trand-lined-voluptas-dolorem-ut-voluptas'}' not found. 1 pattern(s) tried: ['(?P<id>[0-9]+)/(?P<slug>[-a-zA-Z0-9_]+)\\Z']
"GET /1/serv HTTP/1.1" 500 192548
Internal Server Error: /1/serv
Traceback (most recent call last):
  File "D:\work\clients_2023\senv\lib\site-packages\django\core\handlers\exception.py", line 56, in inner
    response = get_response(request)
  File "D:\work\clients_2023\senv\lib\site-packages\django\core\handlers\base.py", line 197, in _get_response
    response = wrapped_callback(request, *callback_args, **callback_kwargs)
  File "D:\work\clients_2023\support\views.py", line 14, in service
    return render(request, 'service.html', context)
  File "D:\work\clients_2023\senv\lib\site-packages\django\shortcuts.py", line 24, in render
    content = loader.render_to_string(template_name, context, request, using=using)
  File "D:\work\clients_2023\senv\lib\site-packages\django\template\loader.py", line 62, in render_to_string
    return template.render(context, request)
  File "D:\work\clients_2023\senv\lib\site-packages\django\template\backends\django.py", line 61, in render
    return self.template.render(context)
  File "D:\work\clients_2023\senv\lib\site-packages\django\template\base.py", line 175, in render
    return self._render(context)
  File "D:\work\clients_2023\senv\lib\site-packages\django\template\base.py", line 167, in _render
    return self.nodelist.render(context)
  File "D:\work\clients_2023\senv\lib\site-packages\django\template\base.py", line 1005, in render
    return SafeString("".join([node.render_annotated(context) for node in self]))
  File "D:\work\clients_2023\senv\lib\site-packages\django\template\base.py", line 1005, in <listcomp>
    return SafeString("".join([node.render_annotated(context) for node in self]))
  File "D:\work\clients_2023\senv\lib\site-packages\django\template\base.py", line 966, in render_annotated
    return self.render(context)
  File "D:\work\clients_2023\senv\lib\site-packages\django\template\loader_tags.py", line 157, in render
    return compiled_parent._render(context)
  File "D:\work\clients_2023\senv\lib\site-packages\django\template\base.py", line 167, in _render
    return self.nodelist.render(context)
  File "D:\work\clients_2023\senv\lib\site-packages\django\template\base.py", line 1005, in render
    return SafeString("".join([node.render_annotated(context) for node in self]))
  File "D:\work\clients_2023\senv\lib\site-packages\django\template\base.py", line 1005, in <listcomp>
    return SafeString("".join([node.render_annotated(context) for node in self]))
  File "D:\work\clients_2023\senv\lib\site-packages\django\template\base.py", line 966, in render_annotated
    return self.render(context)
  File "D:\work\clients_2023\senv\lib\site-packages\django\template\loader_tags.py", line 63, in render
    result = block.nodelist.render(context)
  File "D:\work\clients_2023\senv\lib\site-packages\django\template\base.py", line 1005, in render
    return SafeString("".join([node.render_annotated(context) for node in self]))
  File "D:\work\clients_2023\senv\lib\site-packages\django\template\base.py", line 1005, in <listcomp>
    return SafeString("".join([node.render_annotated(context) for node in self]))
  File "D:\work\clients_2023\senv\lib\site-packages\django\template\base.py", line 966, in render_annotated
    return self.render(context)
  File "D:\work\clients_2023\senv\lib\site-packages\django\template\base.py", line 1064, in render
    output = self.filter_expression.resolve(context)
  File "D:\work\clients_2023\senv\lib\site-packages\django\template\base.py", line 715, in resolve
    obj = self.var.resolve(context)
  File "D:\work\clients_2023\senv\lib\site-packages\django\template\base.py", line 847, in resolve
    value = self._resolve_lookup(context)
  File "D:\work\clients_2023\senv\lib\site-packages\django\template\base.py", line 914, in _resolve_lookup
    current = current()
  File "D:\work\clients_2023\support\models.py", line 45, in get_absolute_url
    return reverse('service', kwargs={'pk': self.pk, 'slug': self.slug})
  File "D:\work\clients_2023\senv\lib\site-packages\django\urls\base.py", line 88, in reverse
    return resolver._reverse_with_prefix(view, prefix, *args, **kwargs)
  File "D:\work\clients_2023\senv\lib\site-packages\django\urls\resolvers.py", line 828, in _reverse_with_prefix
    raise NoReverseMatch(msg)
django.urls.exceptions.NoReverseMatch: Reverse for 'service' with keyword arguments '{'pk': 1, 'slug': 'temporibus-et-in-vero-dicta-aut-eius-lidero-plastis-trand-lined-voluptas-dolorem-ut-voluptas'}' not found. 1 pattern(s) tried: ['(?P<id>[0-9]+)/(?P<slug>[-a-zA-Z0-9_]+)\\Z']
"GET /1/serv HTTP/1.1" 500 192790
Internal Server Error: /services
Traceback (most recent call last):
  File "D:\work\clients_2023\senv\lib\site-packages\django\db\backends\utils.py", line 89, in _execute
    return self.cursor.execute(sql, params)
  File "D:\work\clients_2023\senv\lib\site-packages\django\db\backends\sqlite3\base.py", line 357, in execute
    return Database.Cursor.execute(self, query, params)
sqlite3.OperationalError: no such table: support_service

The above exception was the direct cause of the following exception:

Traceback (most recent call last):
  File "D:\work\clients_2023\senv\lib\site-packages\django\core\handlers\exception.py", line 56, in inner
    response = get_response(request)
  File "D:\work\clients_2023\senv\lib\site-packages\django\core\handlers\base.py", line 197, in _get_response
    response = wrapped_callback(request, *callback_args, **callback_kwargs)
  File "D:\work\clients_2023\webcivils\views.py", line 37, in services
    return render(request, 'services.html', context)
  File "D:\work\clients_2023\senv\lib\site-packages\django\shortcuts.py", line 24, in render
    content = loader.render_to_string(template_name, context, request, using=using)
  File "D:\work\clients_2023\senv\lib\site-packages\django\template\loader.py", line 62, in render_to_string
    return template.render(context, request)
  File "D:\work\clients_2023\senv\lib\site-packages\django\template\backends\django.py", line 61, in render
    return self.template.render(context)
  File "D:\work\clients_2023\senv\lib\site-packages\django\template\base.py", line 175, in render
    return self._render(context)
  File "D:\work\clients_2023\senv\lib\site-packages\django\template\base.py", line 167, in _render
    return self.nodelist.render(context)
  File "D:\work\clients_2023\senv\lib\site-packages\django\template\base.py", line 1005, in render
    return SafeString("".join([node.render_annotated(context) for node in self]))
  File "D:\work\clients_2023\senv\lib\site-packages\django\template\base.py", line 1005, in <listcomp>
    return SafeString("".join([node.render_annotated(context) for node in self]))
  File "D:\work\clients_2023\senv\lib\site-packages\django\template\base.py", line 966, in render_annotated
    return self.render(context)
  File "D:\work\clients_2023\senv\lib\site-packages\django\template\loader_tags.py", line 157, in render
    return compiled_parent._render(context)
  File "D:\work\clients_2023\senv\lib\site-packages\django\template\base.py", line 167, in _render
    return self.nodelist.render(context)
  File "D:\work\clients_2023\senv\lib\site-packages\django\template\base.py", line 1005, in render
    return SafeString("".join([node.render_annotated(context) for node in self]))
  File "D:\work\clients_2023\senv\lib\site-packages\django\template\base.py", line 1005, in <listcomp>
    return SafeString("".join([node.render_annotated(context) for node in self]))
  File "D:\work\clients_2023\senv\lib\site-packages\django\template\base.py", line 966, in render_annotated
    return self.render(context)
  File "D:\work\clients_2023\senv\lib\site-packages\django\template\loader_tags.py", line 63, in render
    result = block.nodelist.render(context)
  File "D:\work\clients_2023\senv\lib\site-packages\django\template\base.py", line 1005, in render
    return SafeString("".join([node.render_annotated(context) for node in self]))
  File "D:\work\clients_2023\senv\lib\site-packages\django\template\base.py", line 1005, in <listcomp>
    return SafeString("".join([node.render_annotated(context) for node in self]))
  File "D:\work\clients_2023\senv\lib\site-packages\django\template\base.py", line 966, in render_annotated
    return self.render(context)
  File "D:\work\clients_2023\senv\lib\site-packages\django\template\defaulttags.py", line 320, in render
    if match:
  File "D:\work\clients_2023\senv\lib\site-packages\django\db\models\query.py", line 408, in __bool__
    self._fetch_all()
  File "D:\work\clients_2023\senv\lib\site-packages\django\db\models\query.py", line 1867, in _fetch_all
    self._result_cache = list(self._iterable_class(self))
  File "D:\work\clients_2023\senv\lib\site-packages\django\db\models\query.py", line 87, in __iter__
    results = compiler.execute_sql(
  File "D:\work\clients_2023\senv\lib\site-packages\django\db\models\sql\compiler.py", line 1398, in execute_sql
    cursor.execute(sql, params)
  File "D:\work\clients_2023\senv\lib\site-packages\django\db\backends\utils.py", line 67, in execute
    return self._execute_with_wrappers(
  File "D:\work\clients_2023\senv\lib\site-packages\django\db\backends\utils.py", line 80, in _execute_with_wrappers
    return executor(sql, params, many, context)
  File "D:\work\clients_2023\senv\lib\site-packages\django\db\backends\utils.py", line 89, in _execute
    return self.cursor.execute(sql, params)
  File "D:\work\clients_2023\senv\lib\site-packages\django\db\utils.py", line 91, in __exit__
    raise dj_exc_value.with_traceback(traceback) from exc_value
  File "D:\work\clients_2023\senv\lib\site-packages\django\db\backends\utils.py", line 89, in _execute
    return self.cursor.execute(sql, params)
  File "D:\work\clients_2023\senv\lib\site-packages\django\db\backends\sqlite3\base.py", line 357, in execute
    return Database.Cursor.execute(self, query, params)
django.db.utils.OperationalError: no such table: support_service
"GET /services HTTP/1.1" 500 145
Internal Server Error: /services
Traceback (most recent call last):
  File "D:\work\clients_2023\senv\lib\site-packages\django\db\backends\utils.py", line 89, in _execute
    return self.cursor.execute(sql, params)
  File "D:\work\clients_2023\senv\lib\site-packages\django\db\backends\sqlite3\base.py", line 357, in execute
    return Database.Cursor.execute(self, query, params)
sqlite3.OperationalError: no such table: support_service

The above exception was the direct cause of the following exception:

Traceback (most recent call last):
  File "D:\work\clients_2023\senv\lib\site-packages\django\core\handlers\exception.py", line 56, in inner
    response = get_response(request)
  File "D:\work\clients_2023\senv\lib\site-packages\django\core\handlers\base.py", line 197, in _get_response
    response = wrapped_callback(request, *callback_args, **callback_kwargs)
  File "D:\work\clients_2023\webcivils\views.py", line 37, in services
    return render(request, 'services.html', context)
  File "D:\work\clients_2023\senv\lib\site-packages\django\shortcuts.py", line 24, in render
    content = loader.render_to_string(template_name, context, request, using=using)
  File "D:\work\clients_2023\senv\lib\site-packages\django\template\loader.py", line 62, in render_to_string
    return template.render(context, request)
  File "D:\work\clients_2023\senv\lib\site-packages\django\template\backends\django.py", line 61, in render
    return self.template.render(context)
  File "D:\work\clients_2023\senv\lib\site-packages\django\template\base.py", line 175, in render
    return self._render(context)
  File "D:\work\clients_2023\senv\lib\site-packages\django\template\base.py", line 167, in _render
    return self.nodelist.render(context)
  File "D:\work\clients_2023\senv\lib\site-packages\django\template\base.py", line 1005, in render
    return SafeString("".join([node.render_annotated(context) for node in self]))
  File "D:\work\clients_2023\senv\lib\site-packages\django\template\base.py", line 1005, in <listcomp>
    return SafeString("".join([node.render_annotated(context) for node in self]))
  File "D:\work\clients_2023\senv\lib\site-packages\django\template\base.py", line 966, in render_annotated
    return self.render(context)
  File "D:\work\clients_2023\senv\lib\site-packages\django\template\loader_tags.py", line 157, in render
    return compiled_parent._render(context)
  File "D:\work\clients_2023\senv\lib\site-packages\django\template\base.py", line 167, in _render
    return self.nodelist.render(context)
  File "D:\work\clients_2023\senv\lib\site-packages\django\template\base.py", line 1005, in render
    return SafeString("".join([node.render_annotated(context) for node in self]))
  File "D:\work\clients_2023\senv\lib\site-packages\django\template\base.py", line 1005, in <listcomp>
    return SafeString("".join([node.render_annotated(context) for node in self]))
  File "D:\work\clients_2023\senv\lib\site-packages\django\template\base.py", line 966, in render_annotated
    return self.render(context)
  File "D:\work\clients_2023\senv\lib\site-packages\django\template\loader_tags.py", line 63, in render
    result = block.nodelist.render(context)
  File "D:\work\clients_2023\senv\lib\site-packages\django\template\base.py", line 1005, in render
    return SafeString("".join([node.render_annotated(context) for node in self]))
  File "D:\work\clients_2023\senv\lib\site-packages\django\template\base.py", line 1005, in <listcomp>
    return SafeString("".join([node.render_annotated(context) for node in self]))
  File "D:\work\clients_2023\senv\lib\site-packages\django\template\base.py", line 966, in render_annotated
    return self.render(context)
  File "D:\work\clients_2023\senv\lib\site-packages\django\template\defaulttags.py", line 320, in render
    if match:
  File "D:\work\clients_2023\senv\lib\site-packages\django\db\models\query.py", line 408, in __bool__
    self._fetch_all()
  File "D:\work\clients_2023\senv\lib\site-packages\django\db\models\query.py", line 1867, in _fetch_all
    self._result_cache = list(self._iterable_class(self))
  File "D:\work\clients_2023\senv\lib\site-packages\django\db\models\query.py", line 87, in __iter__
    results = compiler.execute_sql(
  File "D:\work\clients_2023\senv\lib\site-packages\django\db\models\sql\compiler.py", line 1398, in execute_sql
    cursor.execute(sql, params)
  File "D:\work\clients_2023\senv\lib\site-packages\django\db\backends\utils.py", line 102, in execute
    return super().execute(sql, params)
  File "D:\work\clients_2023\senv\lib\site-packages\django\db\backends\utils.py", line 67, in execute
    return self._execute_with_wrappers(
  File "D:\work\clients_2023\senv\lib\site-packages\django\db\backends\utils.py", line 80, in _execute_with_wrappers
    return executor(sql, params, many, context)
  File "D:\work\clients_2023\senv\lib\site-packages\django\db\backends\utils.py", line 89, in _execute
    return self.cursor.execute(sql, params)
  File "D:\work\clients_2023\senv\lib\site-packages\django\db\utils.py", line 91, in __exit__
    raise dj_exc_value.with_traceback(traceback) from exc_value
  File "D:\work\clients_2023\senv\lib\site-packages\django\db\backends\utils.py", line 89, in _execute
    return self.cursor.execute(sql, params)
  File "D:\work\clients_2023\senv\lib\site-packages\django\db\backends\sqlite3\base.py", line 357, in execute
    return Database.Cursor.execute(self, query, params)
django.db.utils.OperationalError: no such table: support_service
"GET /services HTTP/1.1" 500 214744
Internal Server Error: /services
Traceback (most recent call last):
  File "D:\work\clients_2023\senv\lib\site-packages\django\core\handlers\exception.py", line 56, in inner
    response = get_response(request)
  File "D:\work\clients_2023\senv\lib\site-packages\django\core\handlers\base.py", line 197, in _get_response
    response = wrapped_callback(request, *callback_args, **callback_kwargs)
  File "D:\work\clients_2023\webcivils\views.py", line 37, in services
    context['services'] = Service.objects.all()
NameError: name 'Service' is not defined
"GET /services HTTP/1.1" 500 70285
Internal Server Error: /
Traceback (most recent call last):
  File "D:\work\clients_2023\senv\lib\site-packages\django\core\handlers\exception.py", line 56, in inner
    response = get_response(request)
  File "D:\work\clients_2023\senv\lib\site-packages\django\core\handlers\base.py", line 197, in _get_response
    response = wrapped_callback(request, *callback_args, **callback_kwargs)
  File "D:\work\clients_2023\webcivils\views.py", line 10, in home
    return render(request, 'basic/home.html', context)
  File "D:\work\clients_2023\senv\lib\site-packages\django\shortcuts.py", line 24, in render
    content = loader.render_to_string(template_name, context, request, using=using)
  File "D:\work\clients_2023\senv\lib\site-packages\django\template\loader.py", line 62, in render_to_string
    return template.render(context, request)
  File "D:\work\clients_2023\senv\lib\site-packages\django\template\backends\django.py", line 61, in render
    return self.template.render(context)
  File "D:\work\clients_2023\senv\lib\site-packages\django\template\base.py", line 175, in render
    return self._render(context)
  File "D:\work\clients_2023\senv\lib\site-packages\django\template\base.py", line 167, in _render
    return self.nodelist.render(context)
  File "D:\work\clients_2023\senv\lib\site-packages\django\template\base.py", line 1005, in render
    return SafeString("".join([node.render_annotated(context) for node in self]))
  File "D:\work\clients_2023\senv\lib\site-packages\django\template\base.py", line 1005, in <listcomp>
    return SafeString("".join([node.render_annotated(context) for node in self]))
  File "D:\work\clients_2023\senv\lib\site-packages\django\template\base.py", line 966, in render_annotated
    return self.render(context)
  File "D:\work\clients_2023\senv\lib\site-packages\django\template\loader_tags.py", line 157, in render
    return compiled_parent._render(context)
  File "D:\work\clients_2023\senv\lib\site-packages\django\template\base.py", line 167, in _render
    return self.nodelist.render(context)
  File "D:\work\clients_2023\senv\lib\site-packages\django\template\base.py", line 1005, in render
    return SafeString("".join([node.render_annotated(context) for node in self]))
  File "D:\work\clients_2023\senv\lib\site-packages\django\template\base.py", line 1005, in <listcomp>
    return SafeString("".join([node.render_annotated(context) for node in self]))
  File "D:\work\clients_2023\senv\lib\site-packages\django\template\base.py", line 966, in render_annotated
    return self.render(context)
  File "D:\work\clients_2023\senv\lib\site-packages\django\template\defaulttags.py", line 471, in render
    url = reverse(view_name, args=args, kwargs=kwargs, current_app=current_app)
  File "D:\work\clients_2023\senv\lib\site-packages\django\urls\base.py", line 88, in reverse
    return resolver._reverse_with_prefix(view, prefix, *args, **kwargs)
  File "D:\work\clients_2023\senv\lib\site-packages\django\urls\resolvers.py", line 828, in _reverse_with_prefix
    raise NoReverseMatch(msg)
django.urls.exceptions.NoReverseMatch: Reverse for 'calendar' not found. 'calendar' is not a valid view function or pattern name.
"GET / HTTP/1.1" 500 145
Internal Server Error: /
Traceback (most recent call last):
  File "D:\work\clients_2023\senv\lib\site-packages\django\core\handlers\exception.py", line 56, in inner
    response = get_response(request)
  File "D:\work\clients_2023\senv\lib\site-packages\django\core\handlers\base.py", line 197, in _get_response
    response = wrapped_callback(request, *callback_args, **callback_kwargs)
  File "D:\work\clients_2023\webcivils\views.py", line 10, in home
    return render(request, 'basic/home.html', context)
  File "D:\work\clients_2023\senv\lib\site-packages\django\shortcuts.py", line 24, in render
    content = loader.render_to_string(template_name, context, request, using=using)
  File "D:\work\clients_2023\senv\lib\site-packages\django\template\loader.py", line 62, in render_to_string
    return template.render(context, request)
  File "D:\work\clients_2023\senv\lib\site-packages\django\template\backends\django.py", line 61, in render
    return self.template.render(context)
  File "D:\work\clients_2023\senv\lib\site-packages\django\template\base.py", line 175, in render
    return self._render(context)
  File "D:\work\clients_2023\senv\lib\site-packages\django\template\base.py", line 167, in _render
    return self.nodelist.render(context)
  File "D:\work\clients_2023\senv\lib\site-packages\django\template\base.py", line 1005, in render
    return SafeString("".join([node.render_annotated(context) for node in self]))
  File "D:\work\clients_2023\senv\lib\site-packages\django\template\base.py", line 1005, in <listcomp>
    return SafeString("".join([node.render_annotated(context) for node in self]))
  File "D:\work\clients_2023\senv\lib\site-packages\django\template\base.py", line 966, in render_annotated
    return self.render(context)
  File "D:\work\clients_2023\senv\lib\site-packages\django\template\loader_tags.py", line 157, in render
    return compiled_parent._render(context)
  File "D:\work\clients_2023\senv\lib\site-packages\django\template\base.py", line 167, in _render
    return self.nodelist.render(context)
  File "D:\work\clients_2023\senv\lib\site-packages\django\template\base.py", line 1005, in render
    return SafeString("".join([node.render_annotated(context) for node in self]))
  File "D:\work\clients_2023\senv\lib\site-packages\django\template\base.py", line 1005, in <listcomp>
    return SafeString("".join([node.render_annotated(context) for node in self]))
  File "D:\work\clients_2023\senv\lib\site-packages\django\template\base.py", line 966, in render_annotated
    return self.render(context)
  File "D:\work\clients_2023\senv\lib\site-packages\django\template\defaulttags.py", line 471, in render
    url = reverse(view_name, args=args, kwargs=kwargs, current_app=current_app)
  File "D:\work\clients_2023\senv\lib\site-packages\django\urls\base.py", line 88, in reverse
    return resolver._reverse_with_prefix(view, prefix, *args, **kwargs)
  File "D:\work\clients_2023\senv\lib\site-packages\django\urls\resolvers.py", line 828, in _reverse_with_prefix
    raise NoReverseMatch(msg)
django.urls.exceptions.NoReverseMatch: Reverse for 'calendar' not found. 'calendar' is not a valid view function or pattern name.
"GET / HTTP/1.1" 500 153593
Internal Server Error: /
Traceback (most recent call last):
  File "D:\work\clients_2023\senv\lib\site-packages\django\core\handlers\exception.py", line 56, in inner
    response = get_response(request)
  File "D:\work\clients_2023\senv\lib\site-packages\django\core\handlers\base.py", line 197, in _get_response
    response = wrapped_callback(request, *callback_args, **callback_kwargs)
  File "D:\work\clients_2023\webcivils\views.py", line 10, in home
    return render(request, 'basic/home.html', context)
  File "D:\work\clients_2023\senv\lib\site-packages\django\shortcuts.py", line 24, in render
    content = loader.render_to_string(template_name, context, request, using=using)
  File "D:\work\clients_2023\senv\lib\site-packages\django\template\loader.py", line 62, in render_to_string
    return template.render(context, request)
  File "D:\work\clients_2023\senv\lib\site-packages\django\template\backends\django.py", line 61, in render
    return self.template.render(context)
  File "D:\work\clients_2023\senv\lib\site-packages\django\template\base.py", line 175, in render
    return self._render(context)
  File "D:\work\clients_2023\senv\lib\site-packages\django\template\base.py", line 167, in _render
    return self.nodelist.render(context)
  File "D:\work\clients_2023\senv\lib\site-packages\django\template\base.py", line 1005, in render
    return SafeString("".join([node.render_annotated(context) for node in self]))
  File "D:\work\clients_2023\senv\lib\site-packages\django\template\base.py", line 1005, in <listcomp>
    return SafeString("".join([node.render_annotated(context) for node in self]))
  File "D:\work\clients_2023\senv\lib\site-packages\django\template\base.py", line 966, in render_annotated
    return self.render(context)
  File "D:\work\clients_2023\senv\lib\site-packages\django\template\loader_tags.py", line 157, in render
    return compiled_parent._render(context)
  File "D:\work\clients_2023\senv\lib\site-packages\django\template\base.py", line 167, in _render
    return self.nodelist.render(context)
  File "D:\work\clients_2023\senv\lib\site-packages\django\template\base.py", line 1005, in render
    return SafeString("".join([node.render_annotated(context) for node in self]))
  File "D:\work\clients_2023\senv\lib\site-packages\django\template\base.py", line 1005, in <listcomp>
    return SafeString("".join([node.render_annotated(context) for node in self]))
  File "D:\work\clients_2023\senv\lib\site-packages\django\template\base.py", line 966, in render_annotated
    return self.render(context)
  File "D:\work\clients_2023\senv\lib\site-packages\django\template\defaulttags.py", line 471, in render
    url = reverse(view_name, args=args, kwargs=kwargs, current_app=current_app)
  File "D:\work\clients_2023\senv\lib\site-packages\django\urls\base.py", line 88, in reverse
    return resolver._reverse_with_prefix(view, prefix, *args, **kwargs)
  File "D:\work\clients_2023\senv\lib\site-packages\django\urls\resolvers.py", line 828, in _reverse_with_prefix
    raise NoReverseMatch(msg)
django.urls.exceptions.NoReverseMatch: Reverse for 'subscribe' not found. 'subscribe' is not a valid view function or pattern name.
"GET / HTTP/1.1" 500 154065
Internal Server Error: /contact
Traceback (most recent call last):
  File "D:\work\clients_2023\senv\lib\site-packages\django\core\handlers\exception.py", line 56, in inner
    response = get_response(request)
  File "D:\work\clients_2023\senv\lib\site-packages\django\core\handlers\base.py", line 197, in _get_response
    response = wrapped_callback(request, *callback_args, **callback_kwargs)
  File "D:\work\clients_2023\webcivils\views.py", line 29, in contact
    form.save()
  File "D:\work\clients_2023\senv\lib\site-packages\django\forms\models.py", line 539, in save
    raise ValueError(
ValueError: The Contact could not be created because the data didn't validate.
"POST /contact HTTP/1.1" 500 76870
Internal Server Error: /contact
Traceback (most recent call last):
  File "D:\work\clients_2023\senv\lib\site-packages\django\core\handlers\exception.py", line 56, in inner
    response = get_response(request)
  File "D:\work\clients_2023\senv\lib\site-packages\django\core\handlers\base.py", line 197, in _get_response
    response = wrapped_callback(request, *callback_args, **callback_kwargs)
  File "D:\work\clients_2023\webcivils\views.py", line 29, in contact
    form.save()
  File "D:\work\clients_2023\senv\lib\site-packages\django\forms\models.py", line 539, in save
    raise ValueError(
ValueError: The Contact could not be created because the data didn't validate.
"POST /contact HTTP/1.1" 500 76870
